2017-06-23 09:43:59,917 [Thread-3:5852] [django.request:152] [base:get_response] [WARNING]- Not Found: /favicon.ico
2017-06-23 11:45:19,355 [Thread-2:2836] [django.request:132] [exception:handle_uncaught_exception] [ERROR]- Internal Server Error: /
Traceback (most recent call last):
  File "D:\workspaces\py2_Django_venv\lib\site-packages\django\core\handlers\exception.py", line 42, in inner
    response = get_response(request)
  File "D:\workspaces\py2_Django_venv\lib\site-packages\django\core\handlers\base.py", line 187, in _get_response
    response = self.process_exception_by_middleware(e, request)
  File "D:\workspaces\py2_Django_venv\lib\site-packages\django\core\handlers\base.py", line 185, in _get_response
    response = wrapped_callback(request, *callback_args, **callback_kwargs)
  File "D:\workspaces\django_demo\blog_project\blog\views.py", line 21, in index
    return render(request, 'index.html', locals())
  File "D:\workspaces\py2_Django_venv\lib\site-packages\django\shortcuts.py", line 30, in render
    content = loader.render_to_string(template_name, context, request, using=using)
  File "D:\workspaces\py2_Django_venv\lib\site-packages\django\template\loader.py", line 68, in render_to_string
    return template.render(context, request)
  File "D:\workspaces\py2_Django_venv\lib\site-packages\django\template\backends\django.py", line 66, in render
    return self.template.render(context)
  File "D:\workspaces\py2_Django_venv\lib\site-packages\django\template\base.py", line 206, in render
    with context.bind_template(self):
  File "d:\python27\Lib\contextlib.py", line 17, in __enter__
    return self.gen.next()
  File "D:\workspaces\py2_Django_venv\lib\site-packages\django\template\context.py", line 236, in bind_template
    updates.update(processor(self.request))
TypeError: global_setting() takes no arguments (1 given)
2017-06-23 11:46:41,645 [Thread-2:5288] [django.request:132] [exception:handle_uncaught_exception] [ERROR]- Internal Server Error: /
Traceback (most recent call last):
  File "D:\workspaces\py2_Django_venv\lib\site-packages\django\core\handlers\exception.py", line 42, in inner
    response = get_response(request)
  File "D:\workspaces\py2_Django_venv\lib\site-packages\django\core\handlers\base.py", line 187, in _get_response
    response = self.process_exception_by_middleware(e, request)
  File "D:\workspaces\py2_Django_venv\lib\site-packages\django\core\handlers\base.py", line 185, in _get_response
    response = wrapped_callback(request, *callback_args, **callback_kwargs)
  File "D:\workspaces\django_demo\blog_project\blog\views.py", line 22, in index
    return render(request, 'index.html', locals())
  File "D:\workspaces\py2_Django_venv\lib\site-packages\django\shortcuts.py", line 30, in render
    content = loader.render_to_string(template_name, context, request, using=using)
  File "D:\workspaces\py2_Django_venv\lib\site-packages\django\template\loader.py", line 68, in render_to_string
    return template.render(context, request)
  File "D:\workspaces\py2_Django_venv\lib\site-packages\django\template\backends\django.py", line 66, in render
    return self.template.render(context)
  File "D:\workspaces\py2_Django_venv\lib\site-packages\django\template\base.py", line 206, in render
    with context.bind_template(self):
  File "d:\python27\Lib\contextlib.py", line 17, in __enter__
    return self.gen.next()
  File "D:\workspaces\py2_Django_venv\lib\site-packages\django\template\context.py", line 236, in bind_template
    updates.update(processor(self.request))
TypeError: global_setting() takes no arguments (1 given)
2017-06-23 11:46:44,128 [Thread-8:3092] [django.request:132] [exception:handle_uncaught_exception] [ERROR]- Internal Server Error: /
Traceback (most recent call last):
  File "D:\workspaces\py2_Django_venv\lib\site-packages\django\core\handlers\exception.py", line 42, in inner
    response = get_response(request)
  File "D:\workspaces\py2_Django_venv\lib\site-packages\django\core\handlers\base.py", line 187, in _get_response
    response = self.process_exception_by_middleware(e, request)
  File "D:\workspaces\py2_Django_venv\lib\site-packages\django\core\handlers\base.py", line 185, in _get_response
    response = wrapped_callback(request, *callback_args, **callback_kwargs)
  File "D:\workspaces\django_demo\blog_project\blog\views.py", line 22, in index
    return render(request, 'index.html', locals())
  File "D:\workspaces\py2_Django_venv\lib\site-packages\django\shortcuts.py", line 30, in render
    content = loader.render_to_string(template_name, context, request, using=using)
  File "D:\workspaces\py2_Django_venv\lib\site-packages\django\template\loader.py", line 68, in render_to_string
    return template.render(context, request)
  File "D:\workspaces\py2_Django_venv\lib\site-packages\django\template\backends\django.py", line 66, in render
    return self.template.render(context)
  File "D:\workspaces\py2_Django_venv\lib\site-packages\django\template\base.py", line 206, in render
    with context.bind_template(self):
  File "d:\python27\Lib\contextlib.py", line 17, in __enter__
    return self.gen.next()
  File "D:\workspaces\py2_Django_venv\lib\site-packages\django\template\context.py", line 236, in bind_template
    updates.update(processor(self.request))
TypeError: global_setting() takes no arguments (1 given)
2017-06-23 11:46:45,414 [Thread-9:752] [django.request:132] [exception:handle_uncaught_exception] [ERROR]- Internal Server Error: /
Traceback (most recent call last):
  File "D:\workspaces\py2_Django_venv\lib\site-packages\django\core\handlers\exception.py", line 42, in inner
    response = get_response(request)
  File "D:\workspaces\py2_Django_venv\lib\site-packages\django\core\handlers\base.py", line 187, in _get_response
    response = self.process_exception_by_middleware(e, request)
  File "D:\workspaces\py2_Django_venv\lib\site-packages\django\core\handlers\base.py", line 185, in _get_response
    response = wrapped_callback(request, *callback_args, **callback_kwargs)
  File "D:\workspaces\django_demo\blog_project\blog\views.py", line 22, in index
    return render(request, 'index.html', locals())
  File "D:\workspaces\py2_Django_venv\lib\site-packages\django\shortcuts.py", line 30, in render
    content = loader.render_to_string(template_name, context, request, using=using)
  File "D:\workspaces\py2_Django_venv\lib\site-packages\django\template\loader.py", line 68, in render_to_string
    return template.render(context, request)
  File "D:\workspaces\py2_Django_venv\lib\site-packages\django\template\backends\django.py", line 66, in render
    return self.template.render(context)
  File "D:\workspaces\py2_Django_venv\lib\site-packages\django\template\base.py", line 206, in render
    with context.bind_template(self):
  File "d:\python27\Lib\contextlib.py", line 17, in __enter__
    return self.gen.next()
  File "D:\workspaces\py2_Django_venv\lib\site-packages\django\template\context.py", line 236, in bind_template
    updates.update(processor(self.request))
TypeError: global_setting() takes no arguments (1 given)
2017-06-23 11:46:46,413 [Thread-10:3968] [django.request:132] [exception:handle_uncaught_exception] [ERROR]- Internal Server Error: /
Traceback (most recent call last):
  File "D:\workspaces\py2_Django_venv\lib\site-packages\django\core\handlers\exception.py", line 42, in inner
    response = get_response(request)
  File "D:\workspaces\py2_Django_venv\lib\site-packages\django\core\handlers\base.py", line 187, in _get_response
    response = self.process_exception_by_middleware(e, request)
  File "D:\workspaces\py2_Django_venv\lib\site-packages\django\core\handlers\base.py", line 185, in _get_response
    response = wrapped_callback(request, *callback_args, **callback_kwargs)
  File "D:\workspaces\django_demo\blog_project\blog\views.py", line 22, in index
    return render(request, 'index.html', locals())
  File "D:\workspaces\py2_Django_venv\lib\site-packages\django\shortcuts.py", line 30, in render
    content = loader.render_to_string(template_name, context, request, using=using)
  File "D:\workspaces\py2_Django_venv\lib\site-packages\django\template\loader.py", line 68, in render_to_string
    return template.render(context, request)
  File "D:\workspaces\py2_Django_venv\lib\site-packages\django\template\backends\django.py", line 66, in render
    return self.template.render(context)
  File "D:\workspaces\py2_Django_venv\lib\site-packages\django\template\base.py", line 206, in render
    with context.bind_template(self):
  File "d:\python27\Lib\contextlib.py", line 17, in __enter__
    return self.gen.next()
  File "D:\workspaces\py2_Django_venv\lib\site-packages\django\template\context.py", line 236, in bind_template
    updates.update(processor(self.request))
TypeError: global_setting() takes no arguments (1 given)
2017-06-23 12:29:57,632 [Thread-2:5820] [django.request:132] [exception:handle_uncaught_exception] [ERROR]- Internal Server Error: /
Traceback (most recent call last):
  File "D:\workspaces\py2_Django_venv\lib\site-packages\django\core\handlers\exception.py", line 42, in inner
    response = get_response(request)
  File "D:\workspaces\py2_Django_venv\lib\site-packages\django\core\handlers\base.py", line 187, in _get_response
    response = self.process_exception_by_middleware(e, request)
  File "D:\workspaces\py2_Django_venv\lib\site-packages\django\core\handlers\base.py", line 185, in _get_response
    response = wrapped_callback(request, *callback_args, **callback_kwargs)
  File "D:\workspaces\django_demo\blog_project\blog\views.py", line 22, in index
    return render(request, 'index.html', locals())
  File "D:\workspaces\py2_Django_venv\lib\site-packages\django\shortcuts.py", line 30, in render
    content = loader.render_to_string(template_name, context, request, using=using)
  File "D:\workspaces\py2_Django_venv\lib\site-packages\django\template\loader.py", line 68, in render_to_string
    return template.render(context, request)
  File "D:\workspaces\py2_Django_venv\lib\site-packages\django\template\backends\django.py", line 66, in render
    return self.template.render(context)
  File "D:\workspaces\py2_Django_venv\lib\site-packages\django\template\base.py", line 206, in render
    with context.bind_template(self):
  File "d:\python27\Lib\contextlib.py", line 17, in __enter__
    return self.gen.next()
  File "D:\workspaces\py2_Django_venv\lib\site-packages\django\template\context.py", line 236, in bind_template
    updates.update(processor(self.request))
TypeError: global_setting() takes no arguments (1 given)
2017-06-23 12:31:24,302 [Thread-7:6028] [django.request:152] [base:get_response] [WARNING]- Not Found: /1668488211@qq.com
2017-06-26 09:24:35,112 [Thread-3:4376] [django.request:152] [base:get_response] [WARNING]- Not Found: /favicon.ico
2017-06-26 09:25:40,924 [Thread-8:2228] [django.request:152] [base:get_response] [WARNING]- Not Found: /p.html
2017-06-26 15:55:47,177 [Thread-6:2324] [django.request:152] [base:get_response] [WARNING]- Not Found: /uploads//kindeditor/2017/6/dd10ef40-5a44-11e7-9598-5404a6e4568a.jpg
2017-06-26 16:43:17,230 [Thread-2:5636] [django.request:132] [exception:handle_uncaught_exception] [ERROR]- Internal Server Error: /
Traceback (most recent call last):
  File "D:\workspaces\py2_Django_venv\lib\site-packages\django\core\handlers\exception.py", line 42, in inner
    response = get_response(request)
  File "D:\workspaces\py2_Django_venv\lib\site-packages\django\core\handlers\base.py", line 187, in _get_response
    response = self.process_exception_by_middleware(e, request)
  File "D:\workspaces\py2_Django_venv\lib\site-packages\django\core\handlers\base.py", line 185, in _get_response
    response = wrapped_callback(request, *callback_args, **callback_kwargs)
  File "D:\workspaces\django_demo\blog_project\blog\views.py", line 23, in index
    return render(request, 'index.html', locals())
  File "D:\workspaces\py2_Django_venv\lib\site-packages\django\shortcuts.py", line 30, in render
    content = loader.render_to_string(template_name, context, request, using=using)
  File "D:\workspaces\py2_Django_venv\lib\site-packages\django\template\loader.py", line 67, in render_to_string
    template = get_template(template_name, using=using)
  File "D:\workspaces\py2_Django_venv\lib\site-packages\django\template\loader.py", line 21, in get_template
    return engine.get_template(template_name)
  File "D:\workspaces\py2_Django_venv\lib\site-packages\django\template\backends\django.py", line 39, in get_template
    return Template(self.engine.get_template(template_name), self)
  File "D:\workspaces\py2_Django_venv\lib\site-packages\django\template\engine.py", line 160, in get_template
    template, origin = self.find_template(template_name)
  File "D:\workspaces\py2_Django_venv\lib\site-packages\django\template\engine.py", line 134, in find_template
    name, template_dirs=dirs, skip=skip,
  File "D:\workspaces\py2_Django_venv\lib\site-packages\django\template\loaders\base.py", line 44, in get_template
    contents, origin, origin.template_name, self.engine,
  File "D:\workspaces\py2_Django_venv\lib\site-packages\django\template\base.py", line 191, in __init__
    self.nodelist = self.compile_nodelist()
  File "D:\workspaces\py2_Django_venv\lib\site-packages\django\template\base.py", line 233, in compile_nodelist
    return parser.parse()
  File "D:\workspaces\py2_Django_venv\lib\site-packages\django\template\base.py", line 519, in parse
    self.extend_nodelist(nodelist, compiled_result, token)
  File "D:\workspaces\py2_Django_venv\lib\site-packages\django\template\base.py", line 537, in extend_nodelist
    token, '%r must be the first tag in the template.' % node,
TemplateSyntaxError: <ExtendsNode: extends 'base.html'> must be the first tag in the template.
2017-06-26 16:43:59,236 [Thread-8:6728] [django.request:132] [exception:handle_uncaught_exception] [ERROR]- Internal Server Error: /
Traceback (most recent call last):
  File "D:\workspaces\py2_Django_venv\lib\site-packages\django\core\handlers\exception.py", line 42, in inner
    response = get_response(request)
  File "D:\workspaces\py2_Django_venv\lib\site-packages\django\core\handlers\base.py", line 187, in _get_response
    response = self.process_exception_by_middleware(e, request)
  File "D:\workspaces\py2_Django_venv\lib\site-packages\django\core\handlers\base.py", line 185, in _get_response
    response = wrapped_callback(request, *callback_args, **callback_kwargs)
  File "D:\workspaces\django_demo\blog_project\blog\views.py", line 23, in index
    return render(request, 'index.html', locals())
  File "D:\workspaces\py2_Django_venv\lib\site-packages\django\shortcuts.py", line 30, in render
    content = loader.render_to_string(template_name, context, request, using=using)
  File "D:\workspaces\py2_Django_venv\lib\site-packages\django\template\loader.py", line 67, in render_to_string
    template = get_template(template_name, using=using)
  File "D:\workspaces\py2_Django_venv\lib\site-packages\django\template\loader.py", line 21, in get_template
    return engine.get_template(template_name)
  File "D:\workspaces\py2_Django_venv\lib\site-packages\django\template\backends\django.py", line 39, in get_template
    return Template(self.engine.get_template(template_name), self)
  File "D:\workspaces\py2_Django_venv\lib\site-packages\django\template\engine.py", line 160, in get_template
    template, origin = self.find_template(template_name)
  File "D:\workspaces\py2_Django_venv\lib\site-packages\django\template\engine.py", line 134, in find_template
    name, template_dirs=dirs, skip=skip,
  File "D:\workspaces\py2_Django_venv\lib\site-packages\django\template\loaders\base.py", line 44, in get_template
    contents, origin, origin.template_name, self.engine,
  File "D:\workspaces\py2_Django_venv\lib\site-packages\django\template\base.py", line 191, in __init__
    self.nodelist = self.compile_nodelist()
  File "D:\workspaces\py2_Django_venv\lib\site-packages\django\template\base.py", line 233, in compile_nodelist
    return parser.parse()
  File "D:\workspaces\py2_Django_venv\lib\site-packages\django\template\base.py", line 519, in parse
    self.extend_nodelist(nodelist, compiled_result, token)
  File "D:\workspaces\py2_Django_venv\lib\site-packages\django\template\base.py", line 537, in extend_nodelist
    token, '%r must be the first tag in the template.' % node,
TemplateSyntaxError: <ExtendsNode: extends 'base.html'> must be the first tag in the template.
2017-06-26 17:13:01,448 [Thread-5:6952] [django.request:152] [base:get_response] [WARNING]- Not Found: /index.html
2017-06-27 10:18:37,582 [Thread-32:6760] [django.request:152] [base:get_response] [WARNING]- Not Found: /favicon.ico
2017-06-27 13:46:12,013 [Thread-28:8168] [django.request:152] [base:get_response] [WARNING]- Not Found: /favicon.ico
2017-06-28 09:34:36,836 [Thread-3:1168] [django.request:152] [base:get_response] [WARNING]- Not Found: /favicon.ico
2017-06-28 09:51:44,980 [Thread-8:6964] [django.request:152] [base:get_response] [WARNING]- Not Found: /archive/index.html
2017-06-28 09:51:56,098 [Thread-9:2532] [django.request:152] [base:get_response] [WARNING]- Not Found: /archive/index.html
2017-06-28 09:54:46,131 [Thread-6:6592] [django.request:152] [base:get_response] [WARNING]- Not Found: /archive/index.html
2017-06-28 14:07:02,036 [Thread-6:6368] [django.request:132] [exception:handle_uncaught_exception] [ERROR]- Internal Server Error: /
Traceback (most recent call last):
  File "D:\workspaces\py2_Django_venv\lib\site-packages\django\core\handlers\exception.py", line 42, in inner
    response = get_response(request)
  File "D:\workspaces\py2_Django_venv\lib\site-packages\django\core\handlers\base.py", line 187, in _get_response
    response = self.process_exception_by_middleware(e, request)
  File "D:\workspaces\py2_Django_venv\lib\site-packages\django\core\handlers\base.py", line 185, in _get_response
    response = wrapped_callback(request, *callback_args, **callback_kwargs)
  File "D:\workspaces\django_demo\blog_project\blog\views.py", line 40, in index
    return render(request, 'index.html', locals())
  File "D:\workspaces\py2_Django_venv\lib\site-packages\django\shortcuts.py", line 30, in render
    content = loader.render_to_string(template_name, context, request, using=using)
  File "D:\workspaces\py2_Django_venv\lib\site-packages\django\template\loader.py", line 68, in render_to_string
    return template.render(context, request)
  File "D:\workspaces\py2_Django_venv\lib\site-packages\django\template\backends\django.py", line 66, in render
    return self.template.render(context)
  File "D:\workspaces\py2_Django_venv\lib\site-packages\django\template\base.py", line 208, in render
    return self._render(context)
  File "D:\workspaces\py2_Django_venv\lib\site-packages\django\template\base.py", line 199, in _render
    return self.nodelist.render(context)
  File "D:\workspaces\py2_Django_venv\lib\site-packages\django\template\base.py", line 994, in render
    bit = node.render_annotated(context)
  File "D:\workspaces\py2_Django_venv\lib\site-packages\django\template\base.py", line 961, in render_annotated
    return self.render(context)
  File "D:\workspaces\py2_Django_venv\lib\site-packages\django\template\loader_tags.py", line 152, in render
    compiled_parent = self.get_parent(context)
  File "D:\workspaces\py2_Django_venv\lib\site-packages\django\template\loader_tags.py", line 149, in get_parent
    return self.find_template(parent, context)
  File "D:\workspaces\py2_Django_venv\lib\site-packages\django\template\loader_tags.py", line 129, in find_template
    template_name, skip=history,
  File "D:\workspaces\py2_Django_venv\lib\site-packages\django\template\engine.py", line 134, in find_template
    name, template_dirs=dirs, skip=skip,
  File "D:\workspaces\py2_Django_venv\lib\site-packages\django\template\loaders\base.py", line 44, in get_template
    contents, origin, origin.template_name, self.engine,
  File "D:\workspaces\py2_Django_venv\lib\site-packages\django\template\base.py", line 191, in __init__
    self.nodelist = self.compile_nodelist()
  File "D:\workspaces\py2_Django_venv\lib\site-packages\django\template\base.py", line 233, in compile_nodelist
    return parser.parse()
  File "D:\workspaces\py2_Django_venv\lib\site-packages\django\template\base.py", line 518, in parse
    raise self.error(token, e)
TemplateSyntaxError: slice requires 2 arguments, 1 provided
2017-06-28 14:07:26,398 [Thread-7:4348] [django.request:132] [exception:handle_uncaught_exception] [ERROR]- Internal Server Error: /
Traceback (most recent call last):
  File "D:\workspaces\py2_Django_venv\lib\site-packages\django\core\handlers\exception.py", line 42, in inner
    response = get_response(request)
  File "D:\workspaces\py2_Django_venv\lib\site-packages\django\core\handlers\base.py", line 187, in _get_response
    response = self.process_exception_by_middleware(e, request)
  File "D:\workspaces\py2_Django_venv\lib\site-packages\django\core\handlers\base.py", line 185, in _get_response
    response = wrapped_callback(request, *callback_args, **callback_kwargs)
  File "D:\workspaces\django_demo\blog_project\blog\views.py", line 40, in index
    return render(request, 'index.html', locals())
  File "D:\workspaces\py2_Django_venv\lib\site-packages\django\shortcuts.py", line 30, in render
    content = loader.render_to_string(template_name, context, request, using=using)
  File "D:\workspaces\py2_Django_venv\lib\site-packages\django\template\loader.py", line 68, in render_to_string
    return template.render(context, request)
  File "D:\workspaces\py2_Django_venv\lib\site-packages\django\template\backends\django.py", line 66, in render
    return self.template.render(context)
  File "D:\workspaces\py2_Django_venv\lib\site-packages\django\template\base.py", line 208, in render
    return self._render(context)
  File "D:\workspaces\py2_Django_venv\lib\site-packages\django\template\base.py", line 199, in _render
    return self.nodelist.render(context)
  File "D:\workspaces\py2_Django_venv\lib\site-packages\django\template\base.py", line 994, in render
    bit = node.render_annotated(context)
  File "D:\workspaces\py2_Django_venv\lib\site-packages\django\template\base.py", line 961, in render_annotated
    return self.render(context)
  File "D:\workspaces\py2_Django_venv\lib\site-packages\django\template\loader_tags.py", line 152, in render
    compiled_parent = self.get_parent(context)
  File "D:\workspaces\py2_Django_venv\lib\site-packages\django\template\loader_tags.py", line 149, in get_parent
    return self.find_template(parent, context)
  File "D:\workspaces\py2_Django_venv\lib\site-packages\django\template\loader_tags.py", line 129, in find_template
    template_name, skip=history,
  File "D:\workspaces\py2_Django_venv\lib\site-packages\django\template\engine.py", line 134, in find_template
    name, template_dirs=dirs, skip=skip,
  File "D:\workspaces\py2_Django_venv\lib\site-packages\django\template\loaders\base.py", line 44, in get_template
    contents, origin, origin.template_name, self.engine,
  File "D:\workspaces\py2_Django_venv\lib\site-packages\django\template\base.py", line 191, in __init__
    self.nodelist = self.compile_nodelist()
  File "D:\workspaces\py2_Django_venv\lib\site-packages\django\template\base.py", line 233, in compile_nodelist
    return parser.parse()
  File "D:\workspaces\py2_Django_venv\lib\site-packages\django\template\base.py", line 518, in parse
    raise self.error(token, e)
TemplateSyntaxError: slice requires 2 arguments, 1 provided
2017-06-28 14:27:13,684 [Thread-23:6400] [django.request:152] [base:get_response] [WARNING]- Not Found: /index.html
2017-06-29 11:24:14,904 [Thread-3:4984] [django.request:152] [base:get_response] [WARNING]- Not Found: /favicon.ico
2017-06-29 11:31:53,571 [Thread-28:4972] [django.request:152] [base:get_response] [WARNING]- Not Found: /article/article/
2017-06-29 11:33:05,785 [Thread-38:5684] [django.request:132] [exception:handle_uncaught_exception] [ERROR]- Internal Server Error: /category/
Traceback (most recent call last):
  File "D:\workspaces\py2_Django_venv\lib\site-packages\django\core\handlers\exception.py", line 42, in inner
    response = get_response(request)
  File "D:\workspaces\py2_Django_venv\lib\site-packages\django\core\handlers\base.py", line 187, in _get_response
    response = self.process_exception_by_middleware(e, request)
  File "D:\workspaces\py2_Django_venv\lib\site-packages\django\core\handlers\base.py", line 185, in _get_response
    response = wrapped_callback(request, *callback_args, **callback_kwargs)
  File "D:\workspaces\django_demo\blog_project\blog\views.py", line 191, in category
    return render(request, 'cate')
  File "D:\workspaces\py2_Django_venv\lib\site-packages\django\shortcuts.py", line 30, in render
    content = loader.render_to_string(template_name, context, request, using=using)
  File "D:\workspaces\py2_Django_venv\lib\site-packages\django\template\loader.py", line 67, in render_to_string
    template = get_template(template_name, using=using)
  File "D:\workspaces\py2_Django_venv\lib\site-packages\django\template\loader.py", line 25, in get_template
    raise TemplateDoesNotExist(template_name, chain=chain)
TemplateDoesNotExist: cate
2017-06-29 11:37:08,980 [Thread-44:3588] [django.request:152] [base:get_response] [WARNING]- Not Found: /article/article/
2017-06-29 13:38:43,546 [Thread-54:3720] [django.request:132] [exception:handle_uncaught_exception] [ERROR]- Internal Server Error: /category/
Traceback (most recent call last):
  File "D:\workspaces\py2_Django_venv\lib\site-packages\django\core\handlers\exception.py", line 42, in inner
    response = get_response(request)
  File "D:\workspaces\py2_Django_venv\lib\site-packages\django\core\handlers\base.py", line 187, in _get_response
    response = self.process_exception_by_middleware(e, request)
  File "D:\workspaces\py2_Django_venv\lib\site-packages\django\core\handlers\base.py", line 185, in _get_response
    response = wrapped_callback(request, *callback_args, **callback_kwargs)
  File "D:\workspaces\django_demo\blog_project\blog\views.py", line 191, in category
    return render(request, 'cate')
  File "D:\workspaces\py2_Django_venv\lib\site-packages\django\shortcuts.py", line 30, in render
    content = loader.render_to_string(template_name, context, request, using=using)
  File "D:\workspaces\py2_Django_venv\lib\site-packages\django\template\loader.py", line 67, in render_to_string
    template = get_template(template_name, using=using)
  File "D:\workspaces\py2_Django_venv\lib\site-packages\django\template\loader.py", line 25, in get_template
    raise TemplateDoesNotExist(template_name, chain=chain)
TemplateDoesNotExist: cate
2017-06-29 13:51:03,325 [Thread-128:5536] [django.request:152] [base:get_response] [WARNING]- Not Found: /article/article/
2017-06-29 14:00:34,065 [Thread-137:3184] [django.request:132] [exception:handle_uncaught_exception] [ERROR]- Internal Server Error: /category/
Traceback (most recent call last):
  File "D:\workspaces\py2_Django_venv\lib\site-packages\django\core\handlers\exception.py", line 42, in inner
    response = get_response(request)
  File "D:\workspaces\py2_Django_venv\lib\site-packages\django\core\handlers\base.py", line 187, in _get_response
    response = self.process_exception_by_middleware(e, request)
  File "D:\workspaces\py2_Django_venv\lib\site-packages\django\core\handlers\base.py", line 185, in _get_response
    response = wrapped_callback(request, *callback_args, **callback_kwargs)
  File "D:\workspaces\django_demo\blog_project\blog\views.py", line 191, in category
    return render(request, 'cate')
  File "D:\workspaces\py2_Django_venv\lib\site-packages\django\shortcuts.py", line 30, in render
    content = loader.render_to_string(template_name, context, request, using=using)
  File "D:\workspaces\py2_Django_venv\lib\site-packages\django\template\loader.py", line 67, in render_to_string
    template = get_template(template_name, using=using)
  File "D:\workspaces\py2_Django_venv\lib\site-packages\django\template\loader.py", line 25, in get_template
    raise TemplateDoesNotExist(template_name, chain=chain)
TemplateDoesNotExist: cate
2017-06-29 14:01:53,112 [Thread-154:6128] [django.request:132] [exception:handle_uncaught_exception] [ERROR]- Internal Server Error: /category/
Traceback (most recent call last):
  File "D:\workspaces\py2_Django_venv\lib\site-packages\django\core\handlers\exception.py", line 42, in inner
    response = get_response(request)
  File "D:\workspaces\py2_Django_venv\lib\site-packages\django\core\handlers\base.py", line 187, in _get_response
    response = self.process_exception_by_middleware(e, request)
  File "D:\workspaces\py2_Django_venv\lib\site-packages\django\core\handlers\base.py", line 185, in _get_response
    response = wrapped_callback(request, *callback_args, **callback_kwargs)
  File "D:\workspaces\django_demo\blog_project\blog\views.py", line 191, in category
    return render(request, 'cate')
  File "D:\workspaces\py2_Django_venv\lib\site-packages\django\shortcuts.py", line 30, in render
    content = loader.render_to_string(template_name, context, request, using=using)
  File "D:\workspaces\py2_Django_venv\lib\site-packages\django\template\loader.py", line 67, in render_to_string
    template = get_template(template_name, using=using)
  File "D:\workspaces\py2_Django_venv\lib\site-packages\django\template\loader.py", line 25, in get_template
    raise TemplateDoesNotExist(template_name, chain=chain)
TemplateDoesNotExist: cate
2017-06-29 14:03:34,966 [Thread-155:6088] [django.request:132] [exception:handle_uncaught_exception] [ERROR]- Internal Server Error: /category/
Traceback (most recent call last):
  File "D:\workspaces\py2_Django_venv\lib\site-packages\django\core\handlers\exception.py", line 42, in inner
    response = get_response(request)
  File "D:\workspaces\py2_Django_venv\lib\site-packages\django\core\handlers\base.py", line 187, in _get_response
    response = self.process_exception_by_middleware(e, request)
  File "D:\workspaces\py2_Django_venv\lib\site-packages\django\core\handlers\base.py", line 185, in _get_response
    response = wrapped_callback(request, *callback_args, **callback_kwargs)
  File "D:\workspaces\django_demo\blog_project\blog\views.py", line 191, in category
    return render(request, 'category.html', locals())
  File "D:\workspaces\py2_Django_venv\lib\site-packages\django\shortcuts.py", line 30, in render
    content = loader.render_to_string(template_name, context, request, using=using)
  File "D:\workspaces\py2_Django_venv\lib\site-packages\django\template\loader.py", line 67, in render_to_string
    template = get_template(template_name, using=using)
  File "D:\workspaces\py2_Django_venv\lib\site-packages\django\template\loader.py", line 25, in get_template
    raise TemplateDoesNotExist(template_name, chain=chain)
TemplateDoesNotExist: cate
2017-06-30 15:20:59,401 [Thread-5:6196] [django.request:152] [base:get_response] [WARNING]- Not Found: /favicon.ico
2017-07-13 10:16:06,994 [Thread-25:5720] [django.request:152] [base:get_response] [WARNING]- Not Found: /favicon.ico
